Workbook

Sheet Daily
A1: ???? | B1: ?????????? | C1: ??????_??? | D1: ????_????????? | E1: ??????????_??? | F1: ???_????? | G1: ???_???? | H1: ??????_??? | I1: ?????_????? | J1: ?????_??? | K1: ???_????? | L1: ???_???? | M1: ????? | N1: ?????????????? | O1: ?????????? | P1: ??????? | Q1: ??? | R1: ?_???_????? | S1: ?????_?_??? | T1: ???????? | U1: ???? | V1: ????? | W1: ???? | X1: ???? | Y1: ????????_??? | Z1: ??_?????????
A2: 739648 | J2: =IF(A2="","",SUMIF(FoodLog!$A:$A,A2,FoodLog!$I:$I)) | K2: =IF(A2="","",SUMIF(FoodLog!$A:$A,A2,FoodLog!$F:$F)) | L2: =IF(A2="","",SUMIF(FoodLog!$A:$A,A2,FoodLog!$G:$G)) | M2: =IF(A2="","",SUMIF(FoodLog!$A:$A,A2,FoodLog!$H:$H)) | N2: =LET(train,B2,cardio,C2,steps,D2,sleep,E2,reg,F2,prod,I2,kcal,J2,p,K2,w_train,0.22,w_steps,0.18,w_sleep,0.20,w_reg,0.10,w_food,0.18,w_prod,0.12,s_train,IF(train="Верх",1,IF(train="Ноги",1,IF(train="Отдых",0.6,IF(train="Пропустил",0.2,0)))),s_steps,IF(steps="15k+",1,IF(steps="12-15k",0.9,IF(steps="10-12k",0.8,IF(steps="7-10k",0.6,IF(steps="5-7k",0.4,IF(steps="<5k",0.2,0)))))),s_sleep,IF(sleep=">8",0.9,IF(sleep="6-8",1,IF(sleep="<6",0.2,0))),s_reg,IF(reg="Не сбит",1,IF(reg="Сбит",0.3,0)),s_food,IF(AND(kcal>0,p>0),MIN(1, (p/120))*0.6 + MIN(1, MAX(0,1-ABS(kcal-2200)/600))*0.4,0),s_prod,IF(prod="100%",1,IF(prod="75%",0.8,IF(prod="50%",0.6,IF(prod="25%",0.35,IF(prod="0%",0.1,0)))),ROUND(100*(w_train*s_train + w_steps*s_steps + w_sleep*s_sleep + w_reg*s_reg + w_food*s_food + w_prod*s_prod),0)) | O2: =TEXTJOIN(", ",TRUE,IF(B2="","тренировка",""),IF(D2="","шаги",""),IF(E2="","сон",""),IF(F2="","режим",""),IF(G2="","настроение",""),IF(H2="","энергия",""),IF(I2="","продуктивность",""),IF(J2="","еда (ккал)","")) | U2: =IF($A2="","",IF(SUMIF(FoodLog!$A:$A,$A2,FoodLog!$I:$I)=0,"",SUMIF(FoodLog!$A:$A,$A2,FoodLog!$I:$I))) | V2: =IF($A2="","",IF(SUMIF(FoodLog!$A:$A,$A2,FoodLog!$F:$F)=0,"",SUMIF(FoodLog!$A:$A,$A2,FoodLog!$F:$F))) | W2: =IF($A2="","",IF(SUMIF(FoodLog!$A:$A,$A2,FoodLog!$G:$G)=0,"",SUMIF(FoodLog!$A:$A,$A2,FoodLog!$G:$G))) | X2: =IF($A2="","",IF(SUMIF(FoodLog!$A:$A,$A2,FoodLog!$H:$H)=0,"",SUMIF(FoodLog!$A:$A,$A2,FoodLog!$H:$H))) | Y2: =IF($A2="","",IFERROR(ROUND(100*AVERAGE(IF($B2="","",XLOOKUP($B2,FILTER(Dictionaries!$B:$B,Dictionaries!$A:$A="??????????"),FILTER(Dictionaries!$C:$C,Dictionaries!$A:$A="??????????"))),IF($C2="","",MIN($C2/40,1)),IF($D2="","",XLOOKUP($D2,FILTER(Dictionaries!$B:$B,Dictionaries!$A:$A="????"),FILTER(Dictionaries!$C:$C,Dictionaries!$A:$A="????"))),IF($E2="","",MIN($E2/120,1)),IF(OR($F2<>"",$G2<>""),1,""),IF($H2="","",MIN($H2/100,1)),IF($L2="","",XLOOKUP($L2,FILTER(Dictionaries!$B:$B,Dictionaries!$A:$A="???_????"),FILTER(Dictionaries!$C:$C,Dictionaries!$A:$A="???_????"))),IF($M2="","",XLOOKUP($M2,FILTER(Dictionaries!$B:$B,Dictionaries!$A:$A="?????"),FILTER(Dictionaries!$C:$C,Dictionaries!$A:$A="?????"))),IF($N2="","",MIN($N2/100,1)),IF($O2="","",XLOOKUP($O2,FILTER(Dictionaries!$B:$B,Dictionaries!$A:$A="??????????"),FILTER(Dictionaries!$C:$C,Dictionaries!$A:$A="??????????"))),IF($P2="","",XLOOKUP($P2,FILTER(Dictionaries!$B:$B,Dictionaries!$A:$A="???????"),FILTER(Dictionaries!$C:$C,Dictionaries!$A:$A="???????"))),IF($U2="","",LET(t,IF(OR($B2="????",$B2="????"),"train","rest"),k,$U2,p,$V2,f,$W2,c,$X2,k_s,IF(t="train",IF(k="","",IFS(AND(k>=1900,k<=2050),1,AND(k>=1850,k<1900),0.7,AND(k>2050,k<=2100),0.7,TRUE,0.2)),IF(k="","",IFS(AND(k>=1700,k<=1850),1,AND(k>=1650,k<1700),0.7,AND(k>1850,k<=1900),0.7,TRUE,0.2))),p_s,IF(t="train",IF(p="","",IFS(AND(p>=125,p<=135),1,AND(p>=115,p<125),0.7,AND(p>135,p<=145),0.7,AND(p>=105,p<115),0.4,AND(p>145,p<=155),0.4,TRUE,0.2)),IF(p="","",IFS(AND(p>=120,p<=130),1,AND(p>=110,p<120),0.7,AND(p>130,p<=140),0.7,AND(p>=100,p<110),0.4,AND(p>140,p<=150),0.4,TRUE,0.2))),f_s,IF(f="","",IFS(AND(f>=55,f<=65),1,AND(f>=50,f<55),0.7,AND(f>65,f<=70),0.7,AND(f>=45,f<50),0.4,AND(f>70,f<=75),0.4,TRUE,0.2)),c_s,IF(t="train",IF(c="","",IFS(AND(c>=180,c<=210),1,AND(c>=160,c<180),0.7,AND(c>210,c<=230),0.7,AND(c>=140,c<160),0.4,AND(c>230,c<=250),0.4,TRUE,0.2)),IF(c="","",IFS(AND(c>=140,c<=170),1,AND(c>=120,c<140),0.7,AND(c>170,c<=190),0.7,AND(c>=100,c<120),0.4,AND(c>190,c<=210),0.4,TRUE,0.2))),AVERAGE(k_s,p_s,f_s,c_s)))),1),"")) | Z2: =IF($A2="","",TEXTJOIN(", ",TRUE,IF($B2="","??????????",""),IF($C2="","??????",""),IF($D2="","????",""),IF($E2="","??????????",""),IF($F2="","???-?????",""),IF($G2="","???-????",""),IF($H2="","??????",""),IF($L2="","???",""),IF($M2="","?????",""),IF($N2="","??????????????",""),IF($O2="","??????????",""),IF($P2="","???????",""),IF($U2="","???","")))
A3: 739649 | J3: =IF(A3="","",SUMIF(FoodLog!$A:$A,A3,FoodLog!$I:$I)) | K3: =IF(A3="","",SUMIF(FoodLog!$A:$A,A3,FoodLog!$F:$F)) | L3: =IF(A3="","",SUMIF(FoodLog!$A:$A,A3,FoodLog!$G:$G)) | M3: =IF(A3="","",SUMIF(FoodLog!$A:$A,A3,FoodLog!$H:$H)) | N3: =LET(train,B3,cardio,C3,steps,D3,sleep,E3,reg,F3,prod,I3,kcal,J3,p,K3,w_train,0.22,w_steps,0.18,w_sleep,0.20,w_reg,0.10,w_food,0.18,w_prod,0.12,s_train,IF(train="Верх",1,IF(train="Ноги",1,IF(train="Отдых",0.6,IF(train="Пропустил",0.2,0)))),s_steps,IF(steps="15k+",1,IF(steps="12-15k",0.9,IF(steps="10-12k",0.8,IF(steps="7-10k",0.6,IF(steps="5-7k",0.4,IF(steps="<5k",0.2,0)))))),s_sleep,IF(sleep=">8",0.9,IF(sleep="6-8",1,IF(sleep="<6",0.2,0))),s_reg,IF(reg="Не сбит",1,IF(reg="Сбит",0.3,0)),s_food,IF(AND(kcal>0,p>0),MIN(1, (p/120))*0.6 + MIN(1, MAX(0,1-ABS(kcal-2200)/600))*0.4,0),s_prod,IF(prod="100%",1,IF(prod="75%",0.8,IF(prod="50%",0.6,IF(prod="25%",0.35,IF(prod="0%",0.1,0)))),ROUND(100*(w_train*s_train + w_steps*s_steps + w_sleep*s_sleep + w_reg*s_reg + w_food*s_food + w_prod*s_prod),0)) | O3: =TEXTJOIN(", ",TRUE,IF(B3="","тренировка",""),IF(D3="","шаги",""),IF(E3="","сон",""),IF(F3="","режим",""),IF(G3="","настроение",""),IF(H3="","энергия",""),IF(I3="","продуктивность",""),IF(J3="","еда (ккал)","")) | U3: =IF($A3="","",IF(SUMIF(FoodLog!$A:$A,$A3,FoodLog!$I:$I)=0,"",SUMIF(FoodLog!$A:$A,$A3,FoodLog!$I:$I))) | V3: =IF($A3="","",IF(SUMIF(FoodLog!$A:$A,$A3,FoodLog!$F:$F)=0,"",SUMIF(FoodLog!$A:$A,$A3,FoodLog!$F:$F))) | W3: =IF($A3="","",IF(SUMIF(FoodLog!$A:$A,$A3,FoodLog!$G:$G)=0,"",SUMIF(FoodLog!$A:$A,$A3,FoodLog!$G:$G))) | X3: =IF($A3="","",IF(SUMIF(FoodLog!$A:$A,$A3,FoodLog!$H:$H)=0,"",SUMIF(FoodLog!$A:$A,$A3,FoodLog!$H:$H))) | Y3: =IF($A3="","",IFERROR(ROUND(100*AVERAGE(IF($B3="","",XLOOKUP($B3,FILTER(Dictionaries!$B:$B,Dictionaries!$A:$A="??????????"),FILTER(Dictionaries!$C:$C,Dictionaries!$A:$A="??????????"))),IF($C3="","",MIN($C3/40,1)),IF($D3="","",XLOOKUP($D3,FILTER(Dictionaries!$B:$B,Dictionaries!$A:$A="????"),FILTER(Dictionaries!$C:$C,Dictionaries!$A:$A="????"))),IF($E3="","",MIN($E3/120,1)),IF(OR($F3<>"",$G3<>""),1,""),IF($H3="","",MIN($H3/100,1)),IF($L3="","",XLOOKUP($L3,FILTER(Dictionaries!$B:$B,Dictionaries!$A:$A="???_????"),FILTER(Dictionaries!$C:$C,Dictionaries!$A:$A="???_????"))),IF($M3="","",XLOOKUP($M3,FILTER(Dictionaries!$B:$B,Dictionaries!$A:$A="?????"),FILTER(Dictionaries!$C:$C,Dictionaries!$A:$A="?????"))),IF($N3="","",MIN($N3/100,1)),IF($O3="","",XLOOKUP($O3,FILTER(Dictionaries!$B:$B,Dictionaries!$A:$A="??????????"),FILTER(Dictionaries!$C:$C,Dictionaries!$A:$A="??????????"))),IF($P3="","",XLOOKUP($P3,FILTER(Dictionaries!$B:$B,Dictionaries!$A:$A="???????"),FILTER(Dictionaries!$C:$C,Dictionaries!$A:$A="???????"))),IF($U3="","",LET(t,IF(OR($B3="????",$B3="????"),"train","rest"),k,$U3,p,$V3,f,$W3,c,$X3,k_s,IF(t="train",IF(k="","",IFS(AND(k>=1900,k<=2050),1,AND(k>=1850,k<1900),0.7,AND(k>2050,k<=2100),0.7,TRUE,0.2)),IF(k="","",IFS(AND(k>=1700,k<=1850),1,AND(k>=1650,k<1700),0.7,AND(k>1850,k<=1900),0.7,TRUE,0.2))),p_s,IF(t="train",IF(p="","",IFS(AND(p>=125,p<=135),1,AND(p>=115,p<125),0.7,AND(p>135,p<=145),0.7,AND(p>=105,p<115),0.4,AND(p>145,p<=155),0.4,TRUE,0.2)),IF(p="","",IFS(AND(p>=120,p<=130),1,AND(p>=110,p<120),0.7,AND(p>130,p<=140),0.7,AND(p>=100,p<110),0.4,AND(p>140,p<=150),0.4,TRUE,0.2))),f_s,IF(f="","",IFS(AND(f>=55,f<=65),1,AND(f>=50,f<55),0.7,AND(f>65,f<=70),0.7,AND(f>=45,f<50),0.4,AND(f>70,f<=75),0.4,TRUE,0.2)),c_s,IF(t="train",IF(c="","",IFS(AND(c>=180,c<=210),1,AND(c>=160,c<180),0.7,AND(c>210,c<=230),0.7,AND(c>=140,c<160),0.4,AND(c>230,c<=250),0.4,TRUE,0.2)),IF(c="","",IFS(AND(c>=140,c<=170),1,AND(c>=120,c<140),0.7,AND(c>170,c<=190),0.7,AND(c>=100,c<120),0.4,AND(c>190,c<=210),0.4,TRUE,0.2))),AVERAGE(k_s,p_s,f_s,c_s)))),1),"")) | Z3: =IF($A3="","",TEXTJOIN(", ",TRUE,IF($B3="","??????????",""),IF($C3="","??????",""),IF($D3="","????",""),IF($E3="","??????????",""),IF($F3="","???-?????",""),IF($G3="","???-????",""),IF($H3="","??????",""),IF($L3="","???",""),IF($M3="","?????",""),IF($N3="","??????????????",""),IF($O3="","??????????",""),IF($P3="","???????",""),IF($U3="","???","")))
A4: 739650 | J4: =IF(A4="","",SUMIF(FoodLog!$A:$A,A4,FoodLog!$I:$I)) | K4: =IF(A4="","",SUMIF(FoodLog!$A:$A,A4,FoodLog!$F:$F)) | L4: =IF(A4="","",SUMIF(FoodLog!$A:$A,A4,FoodLog!$G:$G)) | M4: =IF(A4="","",SUMIF(FoodLog!$A:$A,A4,FoodLog!$H:$H)) | N4: =LET(train,B4,cardio,C4,steps,D4,sleep,E4,reg,F4,prod,I4,kcal,J4,p,K4,w_train,0.22,w_steps,0.18,w_sleep,0.20,w_reg,0.10,w_food,0.18,w_prod,0.12,s_train,IF(train="Верх",1,IF(train="Ноги",1,IF(train="Отдых",0.6,IF(train="Пропустил",0.2,0)))),s_steps,IF(steps="15k+",1,IF(steps="12-15k",0.9,IF(steps="10-12k",0.8,IF(steps="7-10k",0.6,IF(steps="5-7k",0.4,IF(steps="<5k",0.2,0)))))),s_sleep,IF(sleep=">8",0.9,IF(sleep="6-8",1,IF(sleep="<6",0.2,0))),s_reg,IF(reg="Не сбит",1,IF(reg="Сбит",0.3,0)),s_food,IF(AND(kcal>0,p>0),MIN(1, (p/120))*0.6 + MIN(1, MAX(0,1-ABS(kcal-2200)/600))*0.4,0),s_prod,IF(prod="100%",1,IF(prod="75%",0.8,IF(prod="50%",0.6,IF(prod="25%",0.35,IF(prod="0%",0.1,0)))),ROUND(100*(w_train*s_train + w_steps*s_steps + w_sleep*s_sleep + w_reg*s_reg + w_food*s_food + w_prod*s_prod),0)) | O4: =TEXTJOIN(", ",TRUE,IF(B4="","тренировка",""),IF(D4="","шаги",""),IF(E4="","сон",""),IF(F4="","режим",""),IF(G4="","настроение",""),IF(H4="","энергия",""),IF(I4="","продуктивность",""),IF(J4="","еда (ккал)","")) | U4: =IF($A4="","",IF(SUMIF(FoodLog!$A:$A,$A4,FoodLog!$I:$I)=0,"",SUMIF(FoodLog!$A:$A,$A4,FoodLog!$I:$I))) | V4: =IF($A4="","",IF(SUMIF(FoodLog!$A:$A,$A4,FoodLog!$F:$F)=0,"",SUMIF(FoodLog!$A:$A,$A4,FoodLog!$F:$F))) | W4: =IF($A4="","",IF(SUMIF(FoodLog!$A:$A,$A4,FoodLog!$G:$G)=0,"",SUMIF(FoodLog!$A:$A,$A4,FoodLog!$G:$G))) | X4: =IF($A4="","",IF(SUMIF(FoodLog!$A:$A,$A4,FoodLog!$H:$H)=0,"",SUMIF(FoodLog!$A:$A,$A4,FoodLog!$H:$H))) | Y4: =IF($A4="","",IFERROR(ROUND(100*AVERAGE(IF($B4="","",XLOOKUP($B4,FILTER(Dictionaries!$B:$B,Dictionaries!$A:$A="??????????"),FILTER(Dictionaries!$C:$C,Dictionaries!$A:$A="??????????"))),IF($C4="","",MIN($C4/40,1)),IF($D4="","",XLOOKUP($D4,FILTER(Dictionaries!$B:$B,Dictionaries!$A:$A="????"),FILTER(Dictionaries!$C:$C,Dictionaries!$A:$A="????"))),IF($E4="","",MIN($E4/120,1)),IF(OR($F4<>"",$G4<>""),1,""),IF($H4="","",MIN($H4/100,1)),IF($L4="","",XLOOKUP($L4,FILTER(Dictionaries!$B:$B,Dictionaries!$A:$A="???_????"),FILTER(Dictionaries!$C:$C,Dictionaries!$A:$A="???_????"))),IF($M4="","",XLOOKUP($M4,FILTER(Dictionaries!$B:$B,Dictionaries!$A:$A="?????"),FILTER(Dictionaries!$C:$C,Dictionaries!$A:$A="?????"))),IF($N4="","",MIN($N4/100,1)),IF($O4="","",XLOOKUP($O4,FILTER(Dictionaries!$B:$B,Dictionaries!$A:$A="??????????"),FILTER(Dictionaries!$C:$C,Dictionaries!$A:$A="??????????"))),IF($P4="","",XLOOKUP($P4,FILTER(Dictionaries!$B:$B,Dictionaries!$A:$A="???????"),FILTER(Dictionaries!$C:$C,Dictionaries!$A:$A="???????"))),IF($U4="","",LET(t,IF(OR($B4="????",$B4="????"),"train","rest"),k,$U4,p,$V4,f,$W4,c,$X4,k_s,IF(t="train",IF(k="","",IFS(AND(k>=1900,k<=2050),1,AND(k>=1850,k<1900),0.7,AND(k>2050,k<=2100),0.7,TRUE,0.2)),IF(k="","",IFS(AND(k>=1700,k<=1850),1,AND(k>=1650,k<1700),0.7,AND(k>1850,k<=1900),0.7,TRUE,0.2))),p_s,IF(t="train",IF(p="","",IFS(AND(p>=125,p<=135),1,AND(p>=115,p<125),0.7,AND(p>135,p<=145),0.7,AND(p>=105,p<115),0.4,AND(p>145,p<=155),0.4,TRUE,0.2)),IF(p="","",IFS(AND(p>=120,p<=130),1,AND(p>=110,p<120),0.7,AND(p>130,p<=140),0.7,AND(p>=100,p<110),0.4,AND(p>140,p<=150),0.4,TRUE,0.2))),f_s,IF(f="","",IFS(AND(f>=55,f<=65),1,AND(f>=50,f<55),0.7,AND(f>65,f<=70),0.7,AND(f>=45,f<50),0.4,AND(f>70,f<=75),0.4,TRUE,0.2)),c_s,IF(t="train",IF(c="","",IFS(AND(c>=180,c<=210),1,AND(c>=160,c<180),0.7,AND(c>210,c<=230),0.7,AND(c>=140,c<160),0.4,AND(c>230,c<=250),0.4,TRUE,0.2)),IF(c="","",IFS(AND(c>=140,c<=170),1,AND(c>=120,c<140),0.7,AND(c>170,c<=190),0.7,AND(c>=100,c<120),0.4,AND(c>190,c<=210),0.4,TRUE,0.2))),AVERAGE(k_s,p_s,f_s,c_s)))),1),"")) | Z4: =IF($A4="","",TEXTJOIN(", ",TRUE,IF($B4="","??????????",""),IF($C4="","??????",""),IF($D4="","????",""),IF($E4="","??????????",""),IF($F4="","???-?????",""),IF($G4="","???-????",""),IF($H4="","??????",""),IF($L4="","???",""),IF($M4="","?????",""),IF($N4="","??????????????",""),IF($O4="","??????????",""),IF($P4="","???????",""),IF($U4="","???","")))
A5: 739651 | J5: =IF(A5="","",SUMIF(FoodLog!$A:$A,A5,FoodLog!$I:$I)) | K5: =IF(A5="","",SUMIF(FoodLog!$A:$A,A5,FoodLog!$F:$F)) | L5: =IF(A5="","",SUMIF(FoodLog!$A:$A,A5,FoodLog!$G:$G)) | M5: =IF(A5="","",SUMIF(FoodLog!$A:$A,A5,FoodLog!$H:$H)) | N5: =LET(train,B5,cardio,C5,steps,D5,sleep,E5,reg,F5,prod,I5,kcal,J5,p,K5,w_train,0.22,w_steps,0.18,w_sleep,0.20,w_reg,0.10,w_food,0.18,w_prod,0.12,s_train,IF(train="Верх",1,IF(train="Ноги",1,IF(train="Отдых",0.6,IF(train="Пропустил",0.2,0)))),s_steps,IF(steps="15k+",1,IF(steps="12-15k",0.9,IF(steps="10-12k",0.8,IF(steps="7-10k",0.6,IF(steps="5-7k",0.4,IF(steps="<5k",0.2,0)))))),s_sleep,IF(sleep=">8",0.9,IF(sleep="6-8",1,IF(sleep="<6",0.2,0))),s_reg,IF(reg="Не сбит",1,IF(reg="Сбит",0.3,0)),s_food,IF(AND(kcal>0,p>0),MIN(1, (p/120))*0.6 + MIN(1, MAX(0,1-ABS(kcal-2200)/600))*0.4,0),s_prod,IF(prod="100%",1,IF(prod="75%",0.8,IF(prod="50%",0.6,IF(prod="25%",0.35,IF(prod="0%",0.1,0)))),ROUND(100*(w_train*s_train + w_steps*s_steps + w_sleep*s_sleep + w_reg*s_reg + w_food*s_food + w_prod*s_prod),0)) | O5: =TEXTJOIN(", ",TRUE,IF(B5="","тренировка",""),IF(D5="","шаги",""),IF(E5="","сон",""),IF(F5="","режим",""),IF(G5="","настроение",""),IF(H5="","энергия",""),IF(I5="","продуктивность",""),IF(J5="","еда (ккал)","")) | U5: =IF($A5="","",IF(SUMIF(FoodLog!$A:$A,$A5,FoodLog!$I:$I)=0,"",SUMIF(FoodLog!$A:$A,$A5,FoodLog!$I:$I))) | V5: =IF($A5="","",IF(SUMIF(FoodLog!$A:$A,$A5,FoodLog!$F:$F)=0,"",SUMIF(FoodLog!$A:$A,$A5,FoodLog!$F:$F))) | W5: =IF($A5="","",IF(SUMIF(FoodLog!$A:$A,$A5,FoodLog!$G:$G)=0,"",SUMIF(FoodLog!$A:$A,$A5,FoodLog!$G:$G))) | X5: =IF($A5="","",IF(SUMIF(FoodLog!$A:$A,$A5,FoodLog!$H:$H)=0,"",SUMIF(FoodLog!$A:$A,$A5,FoodLog!$H:$H))) | Y5: =IF($A5="","",IFERROR(ROUND(100*AVERAGE(IF($B5="","",XLOOKUP($B5,FILTER(Dictionaries!$B:$B,Dictionaries!$A:$A="??????????"),FILTER(Dictionaries!$C:$C,Dictionaries!$A:$A="??????????"))),IF($C5="","",MIN($C5/40,1)),IF($D5="","",XLOOKUP($D5,FILTER(Dictionaries!$B:$B,Dictionaries!$A:$A="????"),FILTER(Dictionaries!$C:$C,Dictionaries!$A:$A="????"))),IF($E5="","",MIN($E5/120,1)),IF(OR($F5<>"",$G5<>""),1,""),IF($H5="","",MIN($H5/100,1)),IF($L5="","",XLOOKUP($L5,FILTER(Dictionaries!$B:$B,Dictionaries!$A:$A="???_????"),FILTER(Dictionaries!$C:$C,Dictionaries!$A:$A="???_????"))),IF($M5="","",XLOOKUP($M5,FILTER(Dictionaries!$B:$B,Dictionaries!$A:$A="?????"),FILTER(Dictionaries!$C:$C,Dictionaries!$A:$A="?????"))),IF($N5="","",MIN($N5/100,1)),IF($O5="","",XLOOKUP($O5,FILTER(Dictionaries!$B:$B,Dictionaries!$A:$A="??????????"),FILTER(Dictionaries!$C:$C,Dictionaries!$A:$A="??????????"))),IF($P5="","",XLOOKUP($P5,FILTER(Dictionaries!$B:$B,Dictionaries!$A:$A="???????"),FILTER(Dictionaries!$C:$C,Dictionaries!$A:$A="???????"))),IF($U5="","",LET(t,IF(OR($B5="????",$B5="????"),"train","rest"),k,$U5,p,$V5,f,$W5,c,$X5,k_s,IF(t="train",IF(k="","",IFS(AND(k>=1900,k<=2050),1,AND(k>=1850,k<1900),0.7,AND(k>2050,k<=2100),0.7,TRUE,0.2)),IF(k="","",IFS(AND(k>=1700,k<=1850),1,AND(k>=1650,k<1700),0.7,AND(k>1850,k<=1900),0.7,TRUE,0.2))),p_s,IF(t="train",IF(p="","",IFS(AND(p>=125,p<=135),1,AND(p>=115,p<125),0.7,AND(p>135,p<=145),0.7,AND(p>=105,p<115),0.4,AND(p>145,p<=155),0.4,TRUE,0.2)),IF(p="","",IFS(AND(p>=120,p<=130),1,AND(p>=110,p<120),0.7,AND(p>130,p<=140),0.7,AND(p>=100,p<110),0.4,AND(p>140,p<=150),0.4,TRUE,0.2))),f_s,IF(f="","",IFS(AND(f>=55,f<=65),1,AND(f>=50,f<55),0.7,AND(f>65,f<=70),0.7,AND(f>=45,f<50),0.4,AND(f>70,f<=75),0.4,TRUE,0.2)),c_s,IF(t="train",IF(c="","",IFS(AND(c>=180,c<=210),1,AND(c>=160,c<180),0.7,AND(c>210,c<=230),0.7,AND(c>=140,c<160),0.4,AND(c>230,c<=250),0.4,TRUE,0.2)),IF(c="","",IFS(AND(c>=140,c<=170),1,AND(c>=120,c<140),0.7,AND(c>170,c<=190),0.7,AND(c>=100,c<120),0.4,AND(c>190,c<=210),0.4,TRUE,0.2))),AVERAGE(k_s,p_s,f_s,c_s)))),1),"")) | Z5: =IF($A5="","",TEXTJOIN(", ",TRUE,IF($B5="","??????????",""),IF($C5="","??????",""),IF($D5="","????",""),IF($E5="","??????????",""),IF($F5="","???-?????",""),IF($G5="","???-????",""),IF($H5="","??????",""),IF($L5="","???",""),IF($M5="","?????",""),IF($N5="","??????????????",""),IF($O5="","??????????",""),IF($P5="","???????",""),IF($U5="","???","")))
A6: 739652 | J6: =IF(A6="","",SUMIF(FoodLog!$A:$A,A6,FoodLog!$I:$I)) | K6: =IF(A6="","",SUMIF(FoodLog!$A:$A,A6,FoodLog!$F:$F)) | L6: =IF(A6="","",SUMIF(FoodLog!$A:$A,A6,FoodLog!$G:$G)) | M6: =IF(A6="","",SUMIF(FoodLog!$A:$A,A6,FoodLog!$H:$H)) | N6: =LET(train,B6,cardio,C6,steps,D6,sleep,E6,reg,F6,prod,I6,kcal,J6,p,K6,w_train,0.22,w_steps,0.18,w_sleep,0.20,w_reg,0.10,w_food,0.18,w_prod,0.12,s_train,IF(train="Верх",1,IF(train="Ноги",1,IF(train="Отдых",0.6,IF(train="Пропустил",0.2,0)))),s_steps,IF(steps="15k+",1,IF(steps="12-15k",0.9,IF(steps="10-12k",0.8,IF(steps="7-10k",0.6,IF(steps="5-7k",0.4,IF(steps="<5k",0.2,0)))))),s_sleep,IF(sleep=">8",0.9,IF(sleep="6-8",1,IF(sleep="<6",0.2,0))),s_reg,IF(reg="Не сбит",1,IF(reg="Сбит",0.3,0)),s_food,IF(AND(kcal>0,p>0),MIN(1, (p/120))*0.6 + MIN(1, MAX(0,1-ABS(kcal-2200)/600))*0.4,0),s_prod,IF(prod="100%",1,IF(prod="75%",0.8,IF(prod="50%",0.6,IF(prod="25%",0.35,IF(prod="0%",0.1,0)))),ROUND(100*(w_train*s_train + w_steps*s_steps + w_sleep*s_sleep + w_reg*s_reg + w_food*s_food + w_prod*s_prod),0)) | O6: =TEXTJOIN(", ",TRUE,IF(B6="","тренировка",""),IF(D6="","шаги",""),IF(E6="","сон",""),IF(F6="","режим",""),IF(G6="","настроение",""),IF(H6="","энергия",""),IF(I6="","продуктивность",""),IF(J6="","еда (ккал)","")) | U6: =IF($A6="","",IF(SUMIF(FoodLog!$A:$A,$A6,FoodLog!$I:$I)=0,"",SUMIF(FoodLog!$A:$A,$A6,FoodLog!$I:$I))) | V6: =IF($A6="","",IF(SUMIF(FoodLog!$A:$A,$A6,FoodLog!$F:$F)=0,"",SUMIF(FoodLog!$A:$A,$A6,FoodLog!$F:$F))) | W6: =IF($A6="","",IF(SUMIF(FoodLog!$A:$A,$A6,FoodLog!$G:$G)=0,"",SUMIF(FoodLog!$A:$A,$A6,FoodLog!$G:$G))) | X6: =IF($A6="","",IF(SUMIF(FoodLog!$A:$A,$A6,FoodLog!$H:$H)=0,"",SUMIF(FoodLog!$A:$A,$A6,FoodLog!$H:$H))) | Y6: =IF($A6="","",IFERROR(ROUND(100*AVERAGE(IF($B6="","",XLOOKUP($B6,FILTER(Dictionaries!$B:$B,Dictionaries!$A:$A="??????????"),FILTER(Dictionaries!$C:$C,Dictionaries!$A:$A="??????????"))),IF($C6="","",MIN($C6/40,1)),IF($D6="","",XLOOKUP($D6,FILTER(Dictionaries!$B:$B,Dictionaries!$A:$A="????"),FILTER(Dictionaries!$C:$C,Dictionaries!$A:$A="????"))),IF($E6="","",MIN($E6/120,1)),IF(OR($F6<>"",$G6<>""),1,""),IF($H6="","",MIN($H6/100,1)),IF($L6="","",XLOOKUP($L6,FILTER(Dictionaries!$B:$B,Dictionaries!$A:$A="???_????"),FILTER(Dictionaries!$C:$C,Dictionaries!$A:$A="???_????"))),IF($M6="","",XLOOKUP($M6,FILTER(Dictionaries!$B:$B,Dictionaries!$A:$A="?????"),FILTER(Dictionaries!$C:$C,Dictionaries!$A:$A="?????"))),IF($N6="","",MIN($N6/100,1)),IF($O6="","",XLOOKUP($O6,FILTER(Dictionaries!$B:$B,Dictionaries!$A:$A="??????????"),FILTER(Dictionaries!$C:$C,Dictionaries!$A:$A="??????????"))),IF($P6="","",XLOOKUP($P6,FILTER(Dictionaries!$B:$B,Dictionaries!$A:$A="???????"),FILTER(Dictionaries!$C:$C,Dictionaries!$A:$A="???????"))),IF($U6="","",LET(t,IF(OR($B6="????",$B6="????"),"train","rest"),k,$U6,p,$V6,f,$W6,c,$X6,k_s,IF(t="train",IF(k="","",IFS(AND(k>=1900,k<=2050),1,AND(k>=1850,k<1900),0.7,AND(k>2050,k<=2100),0.7,TRUE,0.2)),IF(k="","",IFS(AND(k>=1700,k<=1850),1,AND(k>=1650,k<1700),0.7,AND(k>1850,k<=1900),0.7,TRUE,0.2))),p_s,IF(t="train",IF(p="","",IFS(AND(p>=125,p<=135),1,AND(p>=115,p<125),0.7,AND(p>135,p<=145),0.7,AND(p>=105,p<115),0.4,AND(p>145,p<=155),0.4,TRUE,0.2)),IF(p="","",IFS(AND(p>=120,p<=130),1,AND(p>=110,p<120),0.7,AND(p>130,p<=140),0.7,AND(p>=100,p<110),0.4,AND(p>140,p<=150),0.4,TRUE,0.2))),f_s,IF(f="","",IFS(AND(f>=55,f<=65),1,AND(f>=50,f<55),0.7,AND(f>65,f<=70),0.7,AND(f>=45,f<50),0.4,AND(f>70,f<=75),0.4,TRUE,0.2)),c_s,IF(t="train",IF(c="","",IFS(AND(c>=180,c<=210),1,AND(c>=160,c<180),0.7,AND(c>210,c<=230),0.7,AND(c>=140,c<160),0.4,AND(c>230,c<=250),0.4,TRUE,0.2)),IF(c="","",IFS(AND(c>=140,c<=170),1,AND(c>=120,c<140),0.7,AND(c>170,c<=190),0.7,AND(c>=100,c<120),0.4,AND(c>190,c<=210),0.4,TRUE,0.2))),AVERAGE(k_s,p_s,f_s,c_s)))),1),"")) | Z6: =IF($A6="","",TEXTJOIN(", ",TRUE,IF($B6="","??????????",""),IF($C6="","??????",""),IF($D6="","????",""),IF($E6="","??????????",""),IF($F6="","???-?????",""),IF($G6="","???-????",""),IF($H6="","??????",""),IF($L6="","???",""),IF($M6="","?????",""),IF($N6="","??????????????",""),IF($O6="","??????????",""),IF($P6="","???????",""),IF($U6="","???","")))
A7: 739653 | J7: =IF(A7="","",SUMIF(FoodLog!$A:$A,A7,FoodLog!$I:$I)) | K7: =IF(A7="","",SUMIF(FoodLog!$A:$A,A7,FoodLog!$F:$F)) | L7: =IF(A7="","",SUMIF(FoodLog!$A:$A,A7,FoodLog!$G:$G)) | M7: =IF(A7="","",SUMIF(FoodLog!$A:$A,A7,FoodLog!$H:$H)) | N7: =LET(train,B7,cardio,C7,steps,D7,sleep,E7,reg,F7,prod,I7,kcal,J7,p,K7,w_train,0.22,w_steps,0.18,w_sleep,0.20,w_reg,0.10,w_food,0.18,w_prod,0.12,s_train,IF(train="Верх",1,IF(train="Ноги",1,IF(train="Отдых",0.6,IF(train="Пропустил",0.2,0)))),s_steps,IF(steps="15k+",1,IF(steps="12-15k",0.9,IF(steps="10-12k",0.8,IF(steps="7-10k",0.6,IF(steps="5-7k",0.4,IF(steps="<5k",0.2,0)))))),s_sleep,IF(sleep=">8",0.9,IF(sleep="6-8",1,IF(sleep="<6",0.2,0))),s_reg,IF(reg="Не сбит",1,IF(reg="Сбит",0.3,0)),s_food,IF(AND(kcal>0,p>0),MIN(1, (p/120))*0.6 + MIN(1, MAX(0,1-ABS(kcal-2200)/600))*0.4,0),s_prod,IF(prod="100%",1,IF(prod="75%",0.8,IF(prod="50%",0.6,IF(prod="25%",0.35,IF(prod="0%",0.1,0)))),ROUND(100*(w_train*s_train + w_steps*s_steps + w_sleep*s_sleep + w_reg*s_reg + w_food*s_food + w_prod*s_prod),0)) | O7: =TEXTJOIN(", ",TRUE,IF(B7="","тренировка",""),IF(D7="","шаги",""),IF(E7="","сон",""),IF(F7="","режим",""),IF(G7="","настроение",""),IF(H7="","энергия",""),IF(I7="","продуктивность",""),IF(J7="","еда (ккал)","")) | U7: =IF($A7="","",IF(SUMIF(FoodLog!$A:$A,$A7,FoodLog!$I:$I)=0,"",SUMIF(FoodLog!$A:$A,$A7,FoodLog!$I:$I))) | V7: =IF($A7="","",IF(SUMIF(FoodLog!$A:$A,$A7,FoodLog!$F:$F)=0,"",SUMIF(FoodLog!$A:$A,$A7,FoodLog!$F:$F))) | W7: =IF($A7="","",IF(SUMIF(FoodLog!$A:$A,$A7,FoodLog!$G:$G)=0,"",SUMIF(FoodLog!$A:$A,$A7,FoodLog!$G:$G))) | X7: =IF($A7="","",IF(SUMIF(FoodLog!$A:$A,$A7,FoodLog!$H:$H)=0,"",SUMIF(FoodLog!$A:$A,$A7,FoodLog!$H:$H))) | Y7: =IF($A7="","",IFERROR(ROUND(100*AVERAGE(IF($B7="","",XLOOKUP($B7,FILTER(Dictionaries!$B:$B,Dictionaries!$A:$A="??????????"),FILTER(Dictionaries!$C:$C,Dictionaries!$A:$A="??????????"))),IF($C7="","",MIN($C7/40,1)),IF($D7="","",XLOOKUP($D7,FILTER(Dictionaries!$B:$B,Dictionaries!$A:$A="????"),FILTER(Dictionaries!$C:$C,Dictionaries!$A:$A="????"))),IF($E7="","",MIN($E7/120,1)),IF(OR($F7<>"",$G7<>""),1,""),IF($H7="","",MIN($H7/100,1)),IF($L7="","",XLOOKUP($L7,FILTER(Dictionaries!$B:$B,Dictionaries!$A:$A="???_????"),FILTER(Dictionaries!$C:$C,Dictionaries!$A:$A="???_????"))),IF($M7="","",XLOOKUP($M7,FILTER(Dictionaries!$B:$B,Dictionaries!$A:$A="?????"),FILTER(Dictionaries!$C:$C,Dictionaries!$A:$A="?????"))),IF($N7="","",MIN($N7/100,1)),IF($O7="","",XLOOKUP($O7,FILTER(Dictionaries!$B:$B,Dictionaries!$A:$A="??????????"),FILTER(Dictionaries!$C:$C,Dictionaries!$A:$A="??????????"))),IF($P7="","",XLOOKUP($P7,FILTER(Dictionaries!$B:$B,Dictionaries!$A:$A="???????"),FILTER(Dictionaries!$C:$C,Dictionaries!$A:$A="???????"))),IF($U7="","",LET(t,IF(OR($B7="????",$B7="????"),"train","rest"),k,$U7,p,$V7,f,$W7,c,$X7,k_s,IF(t="train",IF(k="","",IFS(AND(k>=1900,k<=2050),1,AND(k>=1850,k<1900),0.7,AND(k>2050,k<=2100),0.7,TRUE,0.2)),IF(k="","",IFS(AND(k>=1700,k<=1850),1,AND(k>=1650,k<1700),0.7,AND(k>1850,k<=1900),0.7,TRUE,0.2))),p_s,IF(t="train",IF(p="","",IFS(AND(p>=125,p<=135),1,AND(p>=115,p<125),0.7,AND(p>135,p<=145),0.7,AND(p>=105,p<115),0.4,AND(p>145,p<=155),0.4,TRUE,0.2)),IF(p="","",IFS(AND(p>=120,p<=130),1,AND(p>=110,p<120),0.7,AND(p>130,p<=140),0.7,AND(p>=100,p<110),0.4,AND(p>140,p<=150),0.4,TRUE,0.2))),f_s,IF(f="","",IFS(AND(f>=55,f<=65),1,AND(f>=50,f<55),0.7,AND(f>65,f<=70),0.7,AND(f>=45,f<50),0.4,AND(f>70,f<=75),0.4,TRUE,0.2)),c_s,IF(t="train",IF(c="","",IFS(AND(c>=180,c<=210),1,AND(c>=160,c<180),0.7,AND(c>210,c<=230),0.7,AND(c>=140,c<160),0.4,AND(c>230,c<=250),0.4,TRUE,0.2)),IF(c="","",IFS(AND(c>=140,c<=170),1,AND(c>=120,c<140),0.7,AND(c>170,c<=190),0.7,AND(c>=100,c<120),0.4,AND(c>190,c<=210),0.4,TRUE,0.2))),AVERAGE(k_s,p_s,f_s,c_s)))),1),"")) | Z7: =IF($A7="","",TEXTJOIN(", ",TRUE,IF($B7="","??????????",""),IF($C7="","??????",""),IF($D7="","????",""),IF($E7="","??????????",""),IF($F7="","???-?????",""),IF($G7="","???-????",""),IF($H7="","??????",""),IF($L7="","???",""),IF($M7="","?????",""),IF($N7="","??????????????",""),IF($O7="","??????????",""),IF($P7="","???????",""),IF($U7="","???","")))
A8: 739654 | J8: =IF(A8="","",SUMIF(FoodLog!$A:$A,A8,FoodLog!$I:$I)) | K8: =IF(A8="","",SUMIF(FoodLog!$A:$A,A8,FoodLog!$F:$F)) | L8: =IF(A8="","",SUMIF(FoodLog!$A:$A,A8,FoodLog!$G:$G)) | M8: =IF(A8="","",SUMIF(FoodLog!$A:$A,A8,FoodLog!$H:$H)) | N8: =LET(train,B8,cardio,C8,steps,D8,sleep,E8,reg,F8,prod,I8,kcal,J8,p,K8,w_train,0.22,w_steps,0.18,w_sleep,0.20,w_reg,0.10,w_food,0.18,w_prod,0.12,s_train,IF(train="Верх",1,IF(train="Ноги",1,IF(train="Отдых",0.6,IF(train="Пропустил",0.2,0)))),s_steps,IF(steps="15k+",1,IF(steps="12-15k",0.9,IF(steps="10-12k",0.8,IF(steps="7-10k",0.6,IF(steps="5-7k",0.4,IF(steps="<5k",0.2,0)))))),s_sleep,IF(sleep=">8",0.9,IF(sleep="6-8",1,IF(sleep="<6",0.2,0))),s_reg,IF(reg="Не сбит",1,IF(reg="Сбит",0.3,0)),s_food,IF(AND(kcal>0,p>0),MIN(1, (p/120))*0.6 + MIN(1, MAX(0,1-ABS(kcal-2200)/600))*0.4,0),s_prod,IF(prod="100%",1,IF(prod="75%",0.8,IF(prod="50%",0.6,IF(prod="25%",0.35,IF(prod="0%",0.1,0)))),ROUND(100*(w_train*s_train + w_steps*s_steps + w_sleep*s_sleep + w_reg*s_reg + w_food*s_food + w_prod*s_prod),0)) | O8: =TEXTJOIN(", ",TRUE,IF(B8="","тренировка",""),IF(D8="","шаги",""),IF(E8="","сон",""),IF(F8="","режим",""),IF(G8="","настроение",""),IF(H8="","энергия",""),IF(I8="","продуктивность",""),IF(J8="","еда (ккал)","")) | U8: =IF($A8="","",IF(SUMIF(FoodLog!$A:$A,$A8,FoodLog!$I:$I)=0,"",SUMIF(FoodLog!$A:$A,$A8,FoodLog!$I:$I))) | V8: =IF($A8="","",IF(SUMIF(FoodLog!$A:$A,$A8,FoodLog!$F:$F)=0,"",SUMIF(FoodLog!$A:$A,$A8,FoodLog!$F:$F))) | W8: =IF($A8="","",IF(SUMIF(FoodLog!$A:$A,$A8,FoodLog!$G:$G)=0,"",SUMIF(FoodLog!$A:$A,$A8,FoodLog!$G:$G))) | X8: =IF($A8="","",IF(SUMIF(FoodLog!$A:$A,$A8,FoodLog!$H:$H)=0,"",SUMIF(FoodLog!$A:$A,$A8,FoodLog!$H:$H))) | Y8: =IF($A8="","",IFERROR(ROUND(100*AVERAGE(IF($B8="","",XLOOKUP($B8,FILTER(Dictionaries!$B:$B,Dictionaries!$A:$A="??????????"),FILTER(Dictionaries!$C:$C,Dictionaries!$A:$A="??????????"))),IF($C8="","",MIN($C8/40,1)),IF($D8="","",XLOOKUP($D8,FILTER(Dictionaries!$B:$B,Dictionaries!$A:$A="????"),FILTER(Dictionaries!$C:$C,Dictionaries!$A:$A="????"))),IF($E8="","",MIN($E8/120,1)),IF(OR($F8<>"",$G8<>""),1,""),IF($H8="","",MIN($H8/100,1)),IF($L8="","",XLOOKUP($L8,FILTER(Dictionaries!$B:$B,Dictionaries!$A:$A="???_????"),FILTER(Dictionaries!$C:$C,Dictionaries!$A:$A="???_????"))),IF($M8="","",XLOOKUP($M8,FILTER(Dictionaries!$B:$B,Dictionaries!$A:$A="?????"),FILTER(Dictionaries!$C:$C,Dictionaries!$A:$A="?????"))),IF($N8="","",MIN($N8/100,1)),IF($O8="","",XLOOKUP($O8,FILTER(Dictionaries!$B:$B,Dictionaries!$A:$A="??????????"),FILTER(Dictionaries!$C:$C,Dictionaries!$A:$A="??????????"))),IF($P8="","",XLOOKUP($P8,FILTER(Dictionaries!$B:$B,Dictionaries!$A:$A="???????"),FILTER(Dictionaries!$C:$C,Dictionaries!$A:$A="???????"))),IF($U8="","",LET(t,IF(OR($B8="????",$B8="????"),"train","rest"),k,$U8,p,$V8,f,$W8,c,$X8,k_s,IF(t="train",IF(k="","",IFS(AND(k>=1900,k<=2050),1,AND(k>=1850,k<1900),0.7,AND(k>2050,k<=2100),0.7,TRUE,0.2)),IF(k="","",IFS(AND(k>=1700,k<=1850),1,AND(k>=1650,k<1700),0.7,AND(k>1850,k<=1900),0.7,TRUE,0.2))),p_s,IF(t="train",IF(p="","",IFS(AND(p>=125,p<=135),1,AND(p>=115,p<125),0.7,AND(p>135,p<=145),0.7,AND(p>=105,p<115),0.4,AND(p>145,p<=155),0.4,TRUE,0.2)),IF(p="","",IFS(AND(p>=120,p<=130),1,AND(p>=110,p<120),0.7,AND(p>130,p<=140),0.7,AND(p>=100,p<110),0.4,AND(p>140,p<=150),0.4,TRUE,0.2))),f_s,IF(f="","",IFS(AND(f>=55,f<=65),1,AND(f>=50,f<55),0.7,AND(f>65,f<=70),0.7,AND(f>=45,f<50),0.4,AND(f>70,f<=75),0.4,TRUE,0.2)),c_s,IF(t="train",IF(c="","",IFS(AND(c>=180,c<=210),1,AND(c>=160,c<180),0.7,AND(c>210,c<=230),0.7,AND(c>=140,c<160),0.4,AND(c>230,c<=250),0.4,TRUE,0.2)),IF(c="","",IFS(AND(c>=140,c<=170),1,AND(c>=120,c<140),0.7,AND(c>170,c<=190),0.7,AND(c>=100,c<120),0.4,AND(c>190,c<=210),0.4,TRUE,0.2))),AVERAGE(k_s,p_s,f_s,c_s)))),1),"")) | Z8: =IF($A8="","",TEXTJOIN(", ",TRUE,IF($B8="","??????????",""),IF($C8="","??????",""),IF($D8="","????",""),IF($E8="","??????????",""),IF($F8="","???-?????",""),IF($G8="","???-????",""),IF($H8="","??????",""),IF($L8="","???",""),IF($M8="","?????",""),IF($N8="","??????????????",""),IF($O8="","??????????",""),IF($P8="","???????",""),IF($U8="","???","")))
A9: 739655 | J9: =IF(A9="","",SUMIF(FoodLog!$A:$A,A9,FoodLog!$I:$I)) | K9: =IF(A9="","",SUMIF(FoodLog!$A:$A,A9,FoodLog!$F:$F)) | L9: =IF(A9="","",SUMIF(FoodLog!$A:$A,A9,FoodLog!$G:$G)) | M9: =IF(A9="","",SUMIF(FoodLog!$A:$A,A9,FoodLog!$H:$H)) | N9: =LET(train,B9,cardio,C9,steps,D9,sleep,E9,reg,F9,prod,I9,kcal,J9,p,K9,w_train,0.22,w_steps,0.18,w_sleep,0.20,w_reg,0.10,w_food,0.18,w_prod,0.12,s_train,IF(train="Верх",1,IF(train="Ноги",1,IF(train="Отдых",0.6,IF(train="Пропустил",0.2,0)))),s_steps,IF(steps="15k+",1,IF(steps="12-15k",0.9,IF(steps="10-12k",0.8,IF(steps="7-10k",0.6,IF(steps="5-7k",0.4,IF(steps="<5k",0.2,0)))))),s_sleep,IF(sleep=">8",0.9,IF(sleep="6-8",1,IF(sleep="<6",0.2,0))),s_reg,IF(reg="Не сбит",1,IF(reg="Сбит",0.3,0)),s_food,IF(AND(kcal>0,p>0),MIN(1, (p/120))*0.6 + MIN(1, MAX(0,1-ABS(kcal-2200)/600))*0.4,0),s_prod,IF(prod="100%",1,IF(prod="75%",0.8,IF(prod="50%",0.6,IF(prod="25%",0.35,IF(prod="0%",0.1,0)))),ROUND(100*(w_train*s_train + w_steps*s_steps + w_sleep*s_sleep + w_reg*s_reg + w_food*s_food + w_prod*s_prod),0)) | O9: =TEXTJOIN(", ",TRUE,IF(B9="","тренировка",""),IF(D9="","шаги",""),IF(E9="","сон",""),IF(F9="","режим",""),IF(G9="","настроение",""),IF(H9="","энергия",""),IF(I9="","продуктивность",""),IF(J9="","еда (ккал)","")) | U9: =IF($A9="","",IF(SUMIF(FoodLog!$A:$A,$A9,FoodLog!$I:$I)=0,"",SUMIF(FoodLog!$A:$A,$A9,FoodLog!$I:$I))) | V9: =IF($A9="","",IF(SUMIF(FoodLog!$A:$A,$A9,FoodLog!$F:$F)=0,"",SUMIF(FoodLog!$A:$A,$A9,FoodLog!$F:$F))) | W9: =IF($A9="","",IF(SUMIF(FoodLog!$A:$A,$A9,FoodLog!$G:$G)=0,"",SUMIF(FoodLog!$A:$A,$A9,FoodLog!$G:$G))) | X9: =IF($A9="","",IF(SUMIF(FoodLog!$A:$A,$A9,FoodLog!$H:$H)=0,"",SUMIF(FoodLog!$A:$A,$A9,FoodLog!$H:$H))) | Y9: =IF($A9="","",IFERROR(ROUND(100*AVERAGE(IF($B9="","",XLOOKUP($B9,FILTER(Dictionaries!$B:$B,Dictionaries!$A:$A="??????????"),FILTER(Dictionaries!$C:$C,Dictionaries!$A:$A="??????????"))),IF($C9="","",MIN($C9/40,1)),IF($D9="","",XLOOKUP($D9,FILTER(Dictionaries!$B:$B,Dictionaries!$A:$A="????"),FILTER(Dictionaries!$C:$C,Dictionaries!$A:$A="????"))),IF($E9="","",MIN($E9/120,1)),IF(OR($F9<>"",$G9<>""),1,""),IF($H9="","",MIN($H9/100,1)),IF($L9="","",XLOOKUP($L9,FILTER(Dictionaries!$B:$B,Dictionaries!$A:$A="???_????"),FILTER(Dictionaries!$C:$C,Dictionaries!$A:$A="???_????"))),IF($M9="","",XLOOKUP($M9,FILTER(Dictionaries!$B:$B,Dictionaries!$A:$A="?????"),FILTER(Dictionaries!$C:$C,Dictionaries!$A:$A="?????"))),IF($N9="","",MIN($N9/100,1)),IF($O9="","",XLOOKUP($O9,FILTER(Dictionaries!$B:$B,Dictionaries!$A:$A="??????????"),FILTER(Dictionaries!$C:$C,Dictionaries!$A:$A="??????????"))),IF($P9="","",XLOOKUP($P9,FILTER(Dictionaries!$B:$B,Dictionaries!$A:$A="???????"),FILTER(Dictionaries!$C:$C,Dictionaries!$A:$A="???????"))),IF($U9="","",LET(t,IF(OR($B9="????",$B9="????"),"train","rest"),k,$U9,p,$V9,f,$W9,c,$X9,k_s,IF(t="train",IF(k="","",IFS(AND(k>=1900,k<=2050),1,AND(k>=1850,k<1900),0.7,AND(k>2050,k<=2100),0.7,TRUE,0.2)),IF(k="","",IFS(AND(k>=1700,k<=1850),1,AND(k>=1650,k<1700),0.7,AND(k>1850,k<=1900),0.7,TRUE,0.2))),p_s,IF(t="train",IF(p="","",IFS(AND(p>=125,p<=135),1,AND(p>=115,p<125),0.7,AND(p>135,p<=145),0.7,AND(p>=105,p<115),0.4,AND(p>145,p<=155),0.4,TRUE,0.2)),IF(p="","",IFS(AND(p>=120,p<=130),1,AND(p>=110,p<120),0.7,AND(p>130,p<=140),0.7,AND(p>=100,p<110),0.4,AND(p>140,p<=150),0.4,TRUE,0.2))),f_s,IF(f="","",IFS(AND(f>=55,f<=65),1,AND(f>=50,f<55),0.7,AND(f>65,f<=70),0.7,AND(f>=45,f<50),0.4,AND(f>70,f<=75),0.4,TRUE,0.2)),c_s,IF(t="train",IF(c="","",IFS(AND(c>=180,c<=210),1,AND(c>=160,c<180),0.7,AND(c>210,c<=230),0.7,AND(c>=140,c<160),0.4,AND(c>230,c<=250),0.4,TRUE,0.2)),IF(c="","",IFS(AND(c>=140,c<=170),1,AND(c>=120,c<140),0.7,AND(c>170,c<=190),0.7,AND(c>=100,c<120),0.4,AND(c>190,c<=210),0.4,TRUE,0.2))),AVERAGE(k_s,p_s,f_s,c_s)))),1),"")) | Z9: =IF($A9="","",TEXTJOIN(", ",TRUE,IF($B9="","??????????",""),IF($C9="","??????",""),IF($D9="","????",""),IF($E9="","??????????",""),IF($F9="","???-?????",""),IF($G9="","???-????",""),IF($H9="","??????",""),IF($L9="","???",""),IF($M9="","?????",""),IF($N9="","??????????????",""),IF($O9="","??????????",""),IF($P9="","???????",""),IF($U9="","???","")))
A10: 739656 | J10: =IF(A10="","",SUMIF(FoodLog!$A:$A,A10,FoodLog!$I:$I)) | K10: =IF(A10="","",SUMIF(FoodLog!$A:$A,A10,FoodLog!$F:$F)) | L10: =IF(A10="","",SUMIF(FoodLog!$A:$A,A10,FoodLog!$G:$G)) | M10: =IF(A10="","",SUMIF(FoodLog!$A:$A,A10,FoodLog!$H:$H)) | N10: =LET(train,B10,cardio,C10,steps,D10,sleep,E10,reg,F10,prod,I10,kcal,J10,p,K10,w_train,0.22,w_steps,0.18,w_sleep,0.20,w_reg,0.10,w_food,0.18,w_prod,0.12,s_train,IF(train="Верх",1,IF(train="Ноги",1,IF(train="Отдых",0.6,IF(train="Пропустил",0.2,0)))),s_steps,IF(steps="15k+",1,IF(steps="12-15k",0.9,IF(steps="10-12k",0.8,IF(steps="7-10k",0.6,IF(steps="5-7k",0.4,IF(steps="<5k",0.2,0)))))),s_sleep,IF(sleep=">8",0.9,IF(sleep="6-8",1,IF(sleep="<6",0.2,0))),s_reg,IF(reg="Не сбит",1,IF(reg="Сбит",0.3,0)),s_food,IF(AND(kcal>0,p>0),MIN(1, (p/120))*0.6 + MIN(1, MAX(0,1-ABS(kcal-2200)/600))*0.4,0),s_prod,IF(prod="100%",1,IF(prod="75%",0.8,IF(prod="50%",0.6,IF(prod="25%",0.35,IF(prod="0%",0.1,0)))),ROUND(100*(w_train*s_train + w_steps*s_steps + w_sleep*s_sleep + w_reg*s_reg + w_food*s_food + w_prod*s_prod),0)) | O10: =TEXTJOIN(", ",TRUE,IF(B10="","тренировка",""),IF(D10="","шаги",""),IF(E10="","сон",""),IF(F10="","режим",""),IF(G10="","настроение",""),IF(H10="","энергия",""),IF(I10="","продуктивность",""),IF(J10="","еда (ккал)","")) | U10: =IF($A10="","",IF(SUMIF(FoodLog!$A:$A,$A10,FoodLog!$I:$I)=0,"",SUMIF(FoodLog!$A:$A,$A10,FoodLog!$I:$I))) | V10: =IF($A10="","",IF(SUMIF(FoodLog!$A:$A,$A10,FoodLog!$F:$F)=0,"",SUMIF(FoodLog!$A:$A,$A10,FoodLog!$F:$F))) | W10: =IF($A10="","",IF(SUMIF(FoodLog!$A:$A,$A10,FoodLog!$G:$G)=0,"",SUMIF(FoodLog!$A:$A,$A10,FoodLog!$G:$G))) | X10: =IF($A10="","",IF(SUMIF(FoodLog!$A:$A,$A10,FoodLog!$H:$H)=0,"",SUMIF(FoodLog!$A:$A,$A10,FoodLog!$H:$H))) | Y10: =IF($A10="","",IFERROR(ROUND(100*AVERAGE(IF($B10="","",XLOOKUP($B10,FILTER(Dictionaries!$B:$B,Dictionaries!$A:$A="??????????"),FILTER(Dictionaries!$C:$C,Dictionaries!$A:$A="??????????"))),IF($C10="","",MIN($C10/40,1)),IF($D10="","",XLOOKUP($D10,FILTER(Dictionaries!$B:$B,Dictionaries!$A:$A="????"),FILTER(Dictionaries!$C:$C,Dictionaries!$A:$A="????"))),IF($E10="","",MIN($E10/120,1)),IF(OR($F10<>"",$G10<>""),1,""),IF($H10="","",MIN($H10/100,1)),IF($L10="","",XLOOKUP($L10,FILTER(Dictionaries!$B:$B,Dictionaries!$A:$A="???_????"),FILTER(Dictionaries!$C:$C,Dictionaries!$A:$A="???_????"))),IF($M10="","",XLOOKUP($M10,FILTER(Dictionaries!$B:$B,Dictionaries!$A:$A="?????"),FILTER(Dictionaries!$C:$C,Dictionaries!$A:$A="?????"))),IF($N10="","",MIN($N10/100,1)),IF($O10="","",XLOOKUP($O10,FILTER(Dictionaries!$B:$B,Dictionaries!$A:$A="??????????"),FILTER(Dictionaries!$C:$C,Dictionaries!$A:$A="??????????"))),IF($P10="","",XLOOKUP($P10,FILTER(Dictionaries!$B:$B,Dictionaries!$A:$A="???????"),FILTER(Dictionaries!$C:$C,Dictionaries!$A:$A="???????"))),IF($U10="","",LET(t,IF(OR($B10="????",$B10="????"),"train","rest"),k,$U10,p,$V10,f,$W10,c,$X10,k_s,IF(t="train",IF(k="","",IFS(AND(k>=1900,k<=2050),1,AND(k>=1850,k<1900),0.7,AND(k>2050,k<=2100),0.7,TRUE,0.2)),IF(k="","",IFS(AND(k>=1700,k<=1850),1,AND(k>=1650,k<1700),0.7,AND(k>1850,k<=1900),0.7,TRUE,0.2))),p_s,IF(t="train",IF(p="","",IFS(AND(p>=125,p<=135),1,AND(p>=115,p<125),0.7,AND(p>135,p<=145),0.7,AND(p>=105,p<115),0.4,AND(p>145,p<=155),0.4,TRUE,0.2)),IF(p="","",IFS(AND(p>=120,p<=130),1,AND(p>=110,p<120),0.7,AND(p>130,p<=140),0.7,AND(p>=100,p<110),0.4,AND(p>140,p<=150),0.4,TRUE,0.2))),f_s,IF(f="","",IFS(AND(f>=55,f<=65),1,AND(f>=50,f<55),0.7,AND(f>65,f<=70),0.7,AND(f>=45,f<50),0.4,AND(f>70,f<=75),0.4,TRUE,0.2)),c_s,IF(t="train",IF(c="","",IFS(AND(c>=180,c<=210),1,AND(c>=160,c<180),0.7,AND(c>210,c<=230),0.7,AND(c>=140,c<160),0.4,AND(c>230,c<=250),0.4,TRUE,0.2)),IF(c="","",IFS(AND(c>=140,c<=170),1,AND(c>=120,c<140),0.7,AND(c>170,c<=190),0.7,AND(c>=100,c<120),0.4,AND(c>190,c<=210),0.4,TRUE,0.2))),AVERAGE(k_s,p_s,f_s,c_s)))),1),"")) | Z10: =IF($A10="","",TEXTJOIN(", ",TRUE,IF($B10="","??????????",""),IF($C10="","??????",""),IF($D10="","????",""),IF($E10="","??????????",""),IF($F10="","???-?????",""),IF($G10="","???-????",""),IF($H10="","??????",""),IF($L10="","???",""),IF($M10="","?????",""),IF($N10="","??????????????",""),IF($O10="","??????????",""),IF($P10="","???????",""),IF($U10="","???","")))
A11: 739657 | J11: =IF(A11="","",SUMIF(FoodLog!$A:$A,A11,FoodLog!$I:$I)) | K11: =IF(A11="","",SUMIF(FoodLog!$A:$A,A11,FoodLog!$F:$F)) | L11: =IF(A11="","",SUMIF(FoodLog!$A:$A,A11,FoodLog!$G:$G)) | M11: =IF(A11="","",SUMIF(FoodLog!$A:$A,A11,FoodLog!$H:$H)) | N11: =LET(train,B11,cardio,C11,steps,D11,sleep,E11,reg,F11,prod,I11,kcal,J11,p,K11,w_train,0.22,w_steps,0.18,w_sleep,0.20,w_reg,0.10,w_food,0.18,w_prod,0.12,s_train,IF(train="Верх",1,IF(train="Ноги",1,IF(train="Отдых",0.6,IF(train="Пропустил",0.2,0)))),s_steps,IF(steps="15k+",1,IF(steps="12-15k",0.9,IF(steps="10-12k",0.8,IF(steps="7-10k",0.6,IF(steps="5-7k",0.4,IF(steps="<5k",0.2,0)))))),s_sleep,IF(sleep=">8",0.9,IF(sleep="6-8",1,IF(sleep="<6",0.2,0))),s_reg,IF(reg="Не сбит",1,IF(reg="Сбит",0.3,0)),s_food,IF(AND(kcal>0,p>0),MIN(1, (p/120))*0.6 + MIN(1, MAX(0,1-ABS(kcal-2200)/600))*0.4,0),s_prod,IF(prod="100%",1,IF(prod="75%",0.8,IF(prod="50%",0.6,IF(prod="25%",0.35,IF(prod="0%",0.1,0)))),ROUND(100*(w_train*s_train + w_steps*s_steps + w_sleep*s_sleep + w_reg*s_reg + w_food*s_food + w_prod*s_prod),0)) | O11: =TEXTJOIN(", ",TRUE,IF(B11="","тренировка",""),IF(D11="","шаги",""),IF(E11="","сон",""),IF(F11="","режим",""),IF(G11="","настроение",""),IF(H11="","энергия",""),IF(I11="","продуктивность",""),IF(J11="","еда (ккал)","")) | U11: =IF($A11="","",IF(SUMIF(FoodLog!$A:$A,$A11,FoodLog!$I:$I)=0,"",SUMIF(FoodLog!$A:$A,$A11,FoodLog!$I:$I))) | V11: =IF($A11="","",IF(SUMIF(FoodLog!$A:$A,$A11,FoodLog!$F:$F)=0,"",SUMIF(FoodLog!$A:$A,$A11,FoodLog!$F:$F))) | W11: =IF($A11="","",IF(SUMIF(FoodLog!$A:$A,$A11,FoodLog!$G:$G)=0,"",SUMIF(FoodLog!$A:$A,$A11,FoodLog!$G:$G))) | X11: =IF($A11="","",IF(SUMIF(FoodLog!$A:$A,$A11,FoodLog!$H:$H)=0,"",SUMIF(FoodLog!$A:$A,$A11,FoodLog!$H:$H))) | Y11: =IF($A11="","",IFERROR(ROUND(100*AVERAGE(IF($B11="","",XLOOKUP($B11,FILTER(Dictionaries!$B:$B,Dictionaries!$A:$A="??????????"),FILTER(Dictionaries!$C:$C,Dictionaries!$A:$A="??????????"))),IF($C11="","",MIN($C11/40,1)),IF($D11="","",XLOOKUP($D11,FILTER(Dictionaries!$B:$B,Dictionaries!$A:$A="????"),FILTER(Dictionaries!$C:$C,Dictionaries!$A:$A="????"))),IF($E11="","",MIN($E11/120,1)),IF(OR($F11<>"",$G11<>""),1,""),IF($H11="","",MIN($H11/100,1)),IF($L11="","",XLOOKUP($L11,FILTER(Dictionaries!$B:$B,Dictionaries!$A:$A="???_????"),FILTER(Dictionaries!$C:$C,Dictionaries!$A:$A="???_????"))),IF($M11="","",XLOOKUP($M11,FILTER(Dictionaries!$B:$B,Dictionaries!$A:$A="?????"),FILTER(Dictionaries!$C:$C,Dictionaries!$A:$A="?????"))),IF($N11="","",MIN($N11/100,1)),IF($O11="","",XLOOKUP($O11,FILTER(Dictionaries!$B:$B,Dictionaries!$A:$A="??????????"),FILTER(Dictionaries!$C:$C,Dictionaries!$A:$A="??????????"))),IF($P11="","",XLOOKUP($P11,FILTER(Dictionaries!$B:$B,Dictionaries!$A:$A="???????"),FILTER(Dictionaries!$C:$C,Dictionaries!$A:$A="???????"))),IF($U11="","",LET(t,IF(OR($B11="????",$B11="????"),"train","rest"),k,$U11,p,$V11,f,$W11,c,$X11,k_s,IF(t="train",IF(k="","",IFS(AND(k>=1900,k<=2050),1,AND(k>=1850,k<1900),0.7,AND(k>2050,k<=2100),0.7,TRUE,0.2)),IF(k="","",IFS(AND(k>=1700,k<=1850),1,AND(k>=1650,k<1700),0.7,AND(k>1850,k<=1900),0.7,TRUE,0.2))),p_s,IF(t="train",IF(p="","",IFS(AND(p>=125,p<=135),1,AND(p>=115,p<125),0.7,AND(p>135,p<=145),0.7,AND(p>=105,p<115),0.4,AND(p>145,p<=155),0.4,TRUE,0.2)),IF(p="","",IFS(AND(p>=120,p<=130),1,AND(p>=110,p<120),0.7,AND(p>130,p<=140),0.7,AND(p>=100,p<110),0.4,AND(p>140,p<=150),0.4,TRUE,0.2))),f_s,IF(f="","",IFS(AND(f>=55,f<=65),1,AND(f>=50,f<55),0.7,AND(f>65,f<=70),0.7,AND(f>=45,f<50),0.4,AND(f>70,f<=75),0.4,TRUE,0.2)),c_s,IF(t="train",IF(c="","",IFS(AND(c>=180,c<=210),1,AND(c>=160,c<180),0.7,AND(c>210,c<=230),0.7,AND(c>=140,c<160),0.4,AND(c>230,c<=250),0.4,TRUE,0.2)),IF(c="","",IFS(AND(c>=140,c<=170),1,AND(c>=120,c<140),0.7,AND(c>170,c<=190),0.7,AND(c>=100,c<120),0.4,AND(c>190,c<=210),0.4,TRUE,0.2))),AVERAGE(k_s,p_s,f_s,c_s)))),1),"")) | Z11: =IF($A11="","",TEXTJOIN(", ",TRUE,IF($B11="","??????????",""),IF($C11="","??????",""),IF($D11="","????",""),IF($E11="","??????????",""),IF($F11="","???-?????",""),IF($G11="","???-????",""),IF($H11="","??????",""),IF($L11="","???",""),IF($M11="","?????",""),IF($N11="","??????????????",""),IF($O11="","??????????",""),IF($P11="","???????",""),IF($U11="","???","")))
A12: 739658 | J12: =IF(A12="","",SUMIF(FoodLog!$A:$A,A12,FoodLog!$I:$I)) | K12: =IF(A12="","",SUMIF(FoodLog!$A:$A,A12,FoodLog!$F:$F)) | L12: =IF(A12="","",SUMIF(FoodLog!$A:$A,A12,FoodLog!$G:$G)) | M12: =IF(A12="","",SUMIF(FoodLog!$A:$A,A12,FoodLog!$H:$H)) | N12: =LET(train,B12,cardio,C12,steps,D12,sleep,E12,reg,F12,prod,I12,kcal,J12,p,K12,w_train,0.22,w_steps,0.18,w_sleep,0.20,w_reg,0.10,w_food,0.18,w_prod,0.12,s_train,IF(train="Верх",1,IF(train="Ноги",1,IF(train="Отдых",0.6,IF(train="Пропустил",0.2,0)))),s_steps,IF(steps="15k+",1,IF(steps="12-15k",0.9,IF(steps="10-12k",0.8,IF(steps="7-10k",0.6,IF(steps="5-7k",0.4,IF(steps="<5k",0.2,0)))))),s_sleep,IF(sleep=">8",0.9,IF(sleep="6-8",1,IF(sleep="<6",0.2,0))),s_reg,IF(reg="Не сбит",1,IF(reg="Сбит",0.3,0)),s_food,IF(AND(kcal>0,p>0),MIN(1, (p/120))*0.6 + MIN(1, MAX(0,1-ABS(kcal-2200)/600))*0.4,0),s_prod,IF(prod="100%",1,IF(prod="75%",0.8,IF(prod="50%",0.6,IF(prod="25%",0.35,IF(prod="0%",0.1,0)))),ROUND(100*(w_train*s_train + w_steps*s_steps + w_sleep*s_sleep + w_reg*s_reg + w_food*s_food + w_prod*s_prod),0)) | O12: =TEXTJOIN(", ",TRUE,IF(B12="","тренировка",""),IF(D12="","шаги",""),IF(E12="","сон",""),IF(F12="","режим",""),IF(G12="","настроение",""),IF(H12="","энергия",""),IF(I12="","продуктивность",""),IF(J12="","еда (ккал)","")) | U12: =IF($A12="","",IF(SUMIF(FoodLog!$A:$A,$A12,FoodLog!$I:$I)=0,"",SUMIF(FoodLog!$A:$A,$A12,FoodLog!$I:$I))) | V12: =IF($A12="","",IF(SUMIF(FoodLog!$A:$A,$A12,FoodLog!$F:$F)=0,"",SUMIF(FoodLog!$A:$A,$A12,FoodLog!$F:$F))) | W12: =IF($A12="","",IF(SUMIF(FoodLog!$A:$A,$A12,FoodLog!$G:$G)=0,"",SUMIF(FoodLog!$A:$A,$A12,FoodLog!$G:$G))) | X12: =IF($A12="","",IF(SUMIF(FoodLog!$A:$A,$A12,FoodLog!$H:$H)=0,"",SUMIF(FoodLog!$A:$A,$A12,FoodLog!$H:$H))) | Y12: =IF($A12="","",IFERROR(ROUND(100*AVERAGE(IF($B12="","",XLOOKUP($B12,FILTER(Dictionaries!$B:$B,Dictionaries!$A:$A="??????????"),FILTER(Dictionaries!$C:$C,Dictionaries!$A:$A="??????????"))),IF($C12="","",MIN($C12/40,1)),IF($D12="","",XLOOKUP($D12,FILTER(Dictionaries!$B:$B,Dictionaries!$A:$A="????"),FILTER(Dictionaries!$C:$C,Dictionaries!$A:$A="????"))),IF($E12="","",MIN($E12/120,1)),IF(OR($F12<>"",$G12<>""),1,""),IF($H12="","",MIN($H12/100,1)),IF($L12="","",XLOOKUP($L12,FILTER(Dictionaries!$B:$B,Dictionaries!$A:$A="???_????"),FILTER(Dictionaries!$C:$C,Dictionaries!$A:$A="???_????"))),IF($M12="","",XLOOKUP($M12,FILTER(Dictionaries!$B:$B,Dictionaries!$A:$A="?????"),FILTER(Dictionaries!$C:$C,Dictionaries!$A:$A="?????"))),IF($N12="","",MIN($N12/100,1)),IF($O12="","",XLOOKUP($O12,FILTER(Dictionaries!$B:$B,Dictionaries!$A:$A="??????????"),FILTER(Dictionaries!$C:$C,Dictionaries!$A:$A="??????????"))),IF($P12="","",XLOOKUP($P12,FILTER(Dictionaries!$B:$B,Dictionaries!$A:$A="???????"),FILTER(Dictionaries!$C:$C,Dictionaries!$A:$A="???????"))),IF($U12="","",LET(t,IF(OR($B12="????",$B12="????"),"train","rest"),k,$U12,p,$V12,f,$W12,c,$X12,k_s,IF(t="train",IF(k="","",IFS(AND(k>=1900,k<=2050),1,AND(k>=1850,k<1900),0.7,AND(k>2050,k<=2100),0.7,TRUE,0.2)),IF(k="","",IFS(AND(k>=1700,k<=1850),1,AND(k>=1650,k<1700),0.7,AND(k>1850,k<=1900),0.7,TRUE,0.2))),p_s,IF(t="train",IF(p="","",IFS(AND(p>=125,p<=135),1,AND(p>=115,p<125),0.7,AND(p>135,p<=145),0.7,AND(p>=105,p<115),0.4,AND(p>145,p<=155),0.4,TRUE,0.2)),IF(p="","",IFS(AND(p>=120,p<=130),1,AND(p>=110,p<120),0.7,AND(p>130,p<=140),0.7,AND(p>=100,p<110),0.4,AND(p>140,p<=150),0.4,TRUE,0.2))),f_s,IF(f="","",IFS(AND(f>=55,f<=65),1,AND(f>=50,f<55),0.7,AND(f>65,f<=70),0.7,AND(f>=45,f<50),0.4,AND(f>70,f<=75),0.4,TRUE,0.2)),c_s,IF(t="train",IF(c="","",IFS(AND(c>=180,c<=210),1,AND(c>=160,c<180),0.7,AND(c>210,c<=230),0.7,AND(c>=140,c<160),0.4,AND(c>230,c<=250),0.4,TRUE,0.2)),IF(c="","",IFS(AND(c>=140,c<=170),1,AND(c>=120,c<140),0.7,AND(c>170,c<=190),0.7,AND(c>=100,c<120),0.4,AND(c>190,c<=210),0.4,TRUE,0.2))),AVERAGE(k_s,p_s,f_s,c_s)))),1),"")) | Z12: =IF($A12="","",TEXTJOIN(", ",TRUE,IF($B12="","??????????",""),IF($C12="","??????",""),IF($D12="","????",""),IF($E12="","??????????",""),IF($F12="","???-?????",""),IF($G12="","???-????",""),IF($H12="","??????",""),IF($L12="","???",""),IF($M12="","?????",""),IF($N12="","??????????????",""),IF($O12="","??????????",""),IF($P12="","???????",""),IF($U12="","???","")))
A13: 739659 | J13: =IF(A13="","",SUMIF(FoodLog!$A:$A,A13,FoodLog!$I:$I)) | K13: =IF(A13="","",SUMIF(FoodLog!$A:$A,A13,FoodLog!$F:$F)) | L13: =IF(A13="","",SUMIF(FoodLog!$A:$A,A13,FoodLog!$G:$G)) | M13: =IF(A13="","",SUMIF(FoodLog!$A:$A,A13,FoodLog!$H:$H)) | N13: =LET(train,B13,cardio,C13,steps,D13,sleep,E13,reg,F13,prod,I13,kcal,J13,p,K13,w_train,0.22,w_steps,0.18,w_sleep,0.20,w_reg,0.10,w_food,0.18,w_prod,0.12,s_train,IF(train="Верх",1,IF(train="Ноги",1,IF(train="Отдых",0.6,IF(train="Пропустил",0.2,0)))),s_steps,IF(steps="15k+",1,IF(steps="12-15k",0.9,IF(steps="10-12k",0.8,IF(steps="7-10k",0.6,IF(steps="5-7k",0.4,IF(steps="<5k",0.2,0)))))),s_sleep,IF(sleep=">8",0.9,IF(sleep="6-8",1,IF(sleep="<6",0.2,0))),s_reg,IF(reg="Не сбит",1,IF(reg="Сбит",0.3,0)),s_food,IF(AND(kcal>0,p>0),MIN(1, (p/120))*0.6 + MIN(1, MAX(0,1-ABS(kcal-2200)/600))*0.4,0),s_prod,IF(prod="100%",1,IF(prod="75%",0.8,IF(prod="50%",0.6,IF(prod="25%",0.35,IF(prod="0%",0.1,0)))),ROUND(100*(w_train*s_train + w_steps*s_steps + w_sleep*s_sleep + w_reg*s_reg + w_food*s_food + w_prod*s_prod),0)) | O13: =TEXTJOIN(", ",TRUE,IF(B13="","тренировка",""),IF(D13="","шаги",""),IF(E13="","сон",""),IF(F13="","режим",""),IF(G13="","настроение",""),IF(H13="","энергия",""),IF(I13="","продуктивность",""),IF(J13="","еда (ккал)","")) | U13: =IF($A13="","",IF(SUMIF(FoodLog!$A:$A,$A13,FoodLog!$I:$I)=0,"",SUMIF(FoodLog!$A:$A,$A13,FoodLog!$I:$I))) | V13: =IF($A13="","",IF(SUMIF(FoodLog!$A:$A,$A13,FoodLog!$F:$F)=0,"",SUMIF(FoodLog!$A:$A,$A13,FoodLog!$F:$F))) | W13: =IF($A13="","",IF(SUMIF(FoodLog!$A:$A,$A13,FoodLog!$G:$G)=0,"",SUMIF(FoodLog!$A:$A,$A13,FoodLog!$G:$G))) | X13: =IF($A13="","",IF(SUMIF(FoodLog!$A:$A,$A13,FoodLog!$H:$H)=0,"",SUMIF(FoodLog!$A:$A,$A13,FoodLog!$H:$H))) | Y13: =IF($A13="","",IFERROR(ROUND(100*AVERAGE(IF($B13="","",XLOOKUP($B13,FILTER(Dictionaries!$B:$B,Dictionaries!$A:$A="??????????"),FILTER(Dictionaries!$C:$C,Dictionaries!$A:$A="??????????"))),IF($C13="","",MIN($C13/40,1)),IF($D13="","",XLOOKUP($D13,FILTER(Dictionaries!$B:$B,Dictionaries!$A:$A="????"),FILTER(Dictionaries!$C:$C,Dictionaries!$A:$A="????"))),IF($E13="","",MIN($E13/120,1)),IF(OR($F13<>"",$G13<>""),1,""),IF($H13="","",MIN($H13/100,1)),IF($L13="","",XLOOKUP($L13,FILTER(Dictionaries!$B:$B,Dictionaries!$A:$A="???_????"),FILTER(Dictionaries!$C:$C,Dictionaries!$A:$A="???_????"))),IF($M13="","",XLOOKUP($M13,FILTER(Dictionaries!$B:$B,Dictionaries!$A:$A="?????"),FILTER(Dictionaries!$C:$C,Dictionaries!$A:$A="?????"))),IF($N13="","",MIN($N13/100,1)),IF($O13="","",XLOOKUP($O13,FILTER(Dictionaries!$B:$B,Dictionaries!$A:$A="??????????"),FILTER(Dictionaries!$C:$C,Dictionaries!$A:$A="??????????"))),IF($P13="","",XLOOKUP($P13,FILTER(Dictionaries!$B:$B,Dictionaries!$A:$A="???????"),FILTER(Dictionaries!$C:$C,Dictionaries!$A:$A="???????"))),IF($U13="","",LET(t,IF(OR($B13="????",$B13="????"),"train","rest"),k,$U13,p,$V13,f,$W13,c,$X13,k_s,IF(t="train",IF(k="","",IFS(AND(k>=1900,k<=2050),1,AND(k>=1850,k<1900),0.7,AND(k>2050,k<=2100),0.7,TRUE,0.2)),IF(k="","",IFS(AND(k>=1700,k<=1850),1,AND(k>=1650,k<1700),0.7,AND(k>1850,k<=1900),0.7,TRUE,0.2))),p_s,IF(t="train",IF(p="","",IFS(AND(p>=125,p<=135),1,AND(p>=115,p<125),0.7,AND(p>135,p<=145),0.7,AND(p>=105,p<115),0.4,AND(p>145,p<=155),0.4,TRUE,0.2)),IF(p="","",IFS(AND(p>=120,p<=130),1,AND(p>=110,p<120),0.7,AND(p>130,p<=140),0.7,AND(p>=100,p<110),0.4,AND(p>140,p<=150),0.4,TRUE,0.2))),f_s,IF(f="","",IFS(AND(f>=55,f<=65),1,AND(f>=50,f<55),0.7,AND(f>65,f<=70),0.7,AND(f>=45,f<50),0.4,AND(f>70,f<=75),0.4,TRUE,0.2)),c_s,IF(t="train",IF(c="","",IFS(AND(c>=180,c<=210),1,AND(c>=160,c<180),0.7,AND(c>210,c<=230),0.7,AND(c>=140,c<160),0.4,AND(c>230,c<=250),0.4,TRUE,0.2)),IF(c="","",IFS(AND(c>=140,c<=170),1,AND(c>=120,c<140),0.7,AND(c>170,c<=190),0.7,AND(c>=100,c<120),0.4,AND(c>190,c<=210),0.4,TRUE,0.2))),AVERAGE(k_s,p_s,f_s,c_s)))),1),"")) | Z13: =IF($A13="","",TEXTJOIN(", ",TRUE,IF($B13="","??????????",""),IF($C13="","??????",""),IF($D13="","????",""),IF($E13="","??????????",""),IF($F13="","???-?????",""),IF($G13="","???-????",""),IF($H13="","??????",""),IF($L13="","???",""),IF($M13="","?????",""),IF($N13="","??????????????",""),IF($O13="","??????????",""),IF($P13="","???????",""),IF($U13="","???","")))
... A91: 739737 | J91: =IF(A91="","",SUMIF(FoodLog!$A:$A,A91,FoodLog!$I:$I)) | K91: =IF(A91="","",SUMIF(FoodLog!$A:$A,A91,FoodLog!$F:$F)) | L91: =IF(A91="","",SUMIF(FoodLog!$A:$A,A91,FoodLog!$G:$G)) | M91: =IF(A91="","",SUMIF(FoodLog!$A:$A,A91,FoodLog!$H:$H)) | N91: =LET(train,B91,cardio,C91,steps,D91,sleep,E91,reg,F91,prod,I91,kcal,J91,p,K91,w_train,0.22,w_steps,0.18,w_sleep,0.20,w_reg,0.10,w_food,0.18,w_prod,0.12,s_train,IF(train="Верх",1,IF(train="Ноги",1,IF(train="Отдых",0.6,IF(train="Пропустил",0.2,0)))),s_steps,IF(steps="15k+",1,IF(steps="12-15k",0.9,IF(steps="10-12k",0.8,IF(steps="7-10k",0.6,IF(steps="5-7k",0.4,IF(steps="<5k",0.2,0)))))),s_sleep,IF(sleep=">8",0.9,IF(sleep="6-8",1,IF(sleep="<6",0.2,0))),s_reg,IF(reg="Не сбит",1,IF(reg="Сбит",0.3,0)),s_food,IF(AND(kcal>0,p>0),MIN(1, (p/120))*0.6 + MIN(1, MAX(0,1-ABS(kcal-2200)/600))*0.4,0),s_prod,IF(prod="100%",1,IF(prod="75%",0.8,IF(prod="50%",0.6,IF(prod="25%",0.35,IF(prod="0%",0.1,0)))),ROUND(100*(w_train*s_train + w_steps*s_steps + w_sleep*s_sleep + w_reg*s_reg + w_food*s_food + w_prod*s_prod),0)) | O91: =TEXTJOIN(", ",TRUE,IF(B91="","тренировка",""),IF(D91="","шаги",""),IF(E91="","сон",""),IF(F91="","режим",""),IF(G91="","настроение",""),IF(H91="","энергия",""),IF(I91="","продуктивность",""),IF(J91="","еда (ккал)","")) | U91: =IF($A91="","",IF(SUMIF(FoodLog!$A:$A,$A91,FoodLog!$I:$I)=0,"",SUMIF(FoodLog!$A:$A,$A91,FoodLog!$I:$I))) | V91: =IF($A91="","",IF(SUMIF(FoodLog!$A:$A,$A91,FoodLog!$F:$F)=0,"",SUMIF(FoodLog!$A:$A,$A91,FoodLog!$F:$F))) | W91: =IF($A91="","",IF(SUMIF(FoodLog!$A:$A,$A91,FoodLog!$G:$G)=0,"",SUMIF(FoodLog!$A:$A,$A91,FoodLog!$G:$G))) | X91: =IF($A91="","",IF(SUMIF(FoodLog!$A:$A,$A91,FoodLog!$H:$H)=0,"",SUMIF(FoodLog!$A:$A,$A91,FoodLog!$H:$H))) | Y91: =IF($A91="","",IFERROR(ROUND(100*AVERAGE(IF($B91="","",XLOOKUP($B91,FILTER(Dictionaries!$B:$B,Dictionaries!$A:$A="??????????"),FILTER(Dictionaries!$C:$C,Dictionaries!$A:$A="??????????"))),IF($C91="","",MIN($C91/40,1)),IF($D91="","",XLOOKUP($D91,FILTER(Dictionaries!$B:$B,Dictionaries!$A:$A="????"),FILTER(Dictionaries!$C:$C,Dictionaries!$A:$A="????"))),IF($E91="","",MIN($E91/120,1)),IF(OR($F91<>"",$G91<>""),1,""),IF($H91="","",MIN($H91/100,1)),IF($L91="","",XLOOKUP($L91,FILTER(Dictionaries!$B:$B,Dictionaries!$A:$A="???_????"),FILTER(Dictionaries!$C:$C,Dictionaries!$A:$A="???_????"))),IF($M91="","",XLOOKUP($M91,FILTER(Dictionaries!$B:$B,Dictionaries!$A:$A="?????"),FILTER(Dictionaries!$C:$C,Dictionaries!$A:$A="?????"))),IF($N91="","",MIN($N91/100,1)),IF($O91="","",XLOOKUP($O91,FILTER(Dictionaries!$B:$B,Dictionaries!$A:$A="??????????"),FILTER(Dictionaries!$C:$C,Dictionaries!$A:$A="??????????"))),IF($P91="","",XLOOKUP($P91,FILTER(Dictionaries!$B:$B,Dictionaries!$A:$A="???????"),FILTER(Dictionaries!$C:$C,Dictionaries!$A:$A="???????"))),IF($U91="","",LET(t,IF(OR($B91="????",$B91="????"),"train","rest"),k,$U91,p,$V91,f,$W91,c,$X91,k_s,IF(t="train",IF(k="","",IFS(AND(k>=1900,k<=2050),1,AND(k>=1850,k<1900),0.7,AND(k>2050,k<=2100),0.7,TRUE,0.2)),IF(k="","",IFS(AND(k>=1700,k<=1850),1,AND(k>=1650,k<1700),0.7,AND(k>1850,k<=1900),0.7,TRUE,0.2))),p_s,IF(t="train",IF(p="","",IFS(AND(p>=125,p<=135),1,AND(p>=115,p<125),0.7,AND(p>135,p<=145),0.7,AND(p>=105,p<115),0.4,AND(p>145,p<=155),0.4,TRUE,0.2)),IF(p="","",IFS(AND(p>=120,p<=130),1,AND(p>=110,p<120),0.7,AND(p>130,p<=140),0.7,AND(p>=100,p<110),0.4,AND(p>140,p<=150),0.4,TRUE,0.2))),f_s,IF(f="","",IFS(AND(f>=55,f<=65),1,AND(f>=50,f<55),0.7,AND(f>65,f<=70),0.7,AND(f>=45,f<50),0.4,AND(f>70,f<=75),0.4,TRUE,0.2)),c_s,IF(t="train",IF(c="","",IFS(AND(c>=180,c<=210),1,AND(c>=160,c<180),0.7,AND(c>210,c<=230),0.7,AND(c>=140,c<160),0.4,AND(c>230,c<=250),0.4,TRUE,0.2)),IF(c="","",IFS(AND(c>=140,c<=170),1,AND(c>=120,c<140),0.7,AND(c>170,c<=190),0.7,AND(c>=100,c<120),0.4,AND(c>190,c<=210),0.4,TRUE,0.2))),AVERAGE(k_s,p_s,f_s,c_s)))),1),"")) | Z91: =IF($A91="","",TEXTJOIN(", ",TRUE,IF($B91="","??????????",""),IF($C91="","??????",""),IF($D91="","????",""),IF($E91="","??????????",""),IF($F91="","???-?????",""),IF($G91="","???-????",""),IF($H91="","??????",""),IF($L91="","???",""),IF($M91="","?????",""),IF($N91="","??????????????",""),IF($O91="","??????????",""),IF($P91="","???????",""),IF($U91="","???","")))
U92: =IF($A92="","",IF(SUMIF(FoodLog!$A:$A,$A92,FoodLog!$I:$I)=0,"",SUMIF(FoodLog!$A:$A,$A92,FoodLog!$I:$I))) | V92: =IF($A92="","",IF(SUMIF(FoodLog!$A:$A,$A92,FoodLog!$F:$F)=0,"",SUMIF(FoodLog!$A:$A,$A92,FoodLog!$F:$F))) | W92: =IF($A92="","",IF(SUMIF(FoodLog!$A:$A,$A92,FoodLog!$G:$G)=0,"",SUMIF(FoodLog!$A:$A,$A92,FoodLog!$G:$G))) | X92: =IF($A92="","",IF(SUMIF(FoodLog!$A:$A,$A92,FoodLog!$H:$H)=0,"",SUMIF(FoodLog!$A:$A,$A92,FoodLog!$H:$H))) | Y92: =IF($A92="","",IFERROR(ROUND(100*AVERAGE(IF($B92="","",XLOOKUP($B92,FILTER(Dictionaries!$B:$B,Dictionaries!$A:$A="??????????"),FILTER(Dictionaries!$C:$C,Dictionaries!$A:$A="??????????"))),IF($C92="","",MIN($C92/40,1)),IF($D92="","",XLOOKUP($D92,FILTER(Dictionaries!$B:$B,Dictionaries!$A:$A="????"),FILTER(Dictionaries!$C:$C,Dictionaries!$A:$A="????"))),IF($E92="","",MIN($E92/120,1)),IF(OR($F92<>"",$G92<>""),1,""),IF($H92="","",MIN($H92/100,1)),IF($L92="","",XLOOKUP($L92,FILTER(Dictionaries!$B:$B,Dictionaries!$A:$A="???_????"),FILTER(Dictionaries!$C:$C,Dictionaries!$A:$A="???_????"))),IF($M92="","",XLOOKUP($M92,FILTER(Dictionaries!$B:$B,Dictionaries!$A:$A="?????"),FILTER(Dictionaries!$C:$C,Dictionaries!$A:$A="?????"))),IF($N92="","",MIN($N92/100,1)),IF($O92="","",XLOOKUP($O92,FILTER(Dictionaries!$B:$B,Dictionaries!$A:$A="??????????"),FILTER(Dictionaries!$C:$C,Dictionaries!$A:$A="??????????"))),IF($P92="","",XLOOKUP($P92,FILTER(Dictionaries!$B:$B,Dictionaries!$A:$A="???????"),FILTER(Dictionaries!$C:$C,Dictionaries!$A:$A="???????"))),IF($U92="","",LET(t,IF(OR($B92="????",$B92="????"),"train","rest"),k,$U92,p,$V92,f,$W92,c,$X92,k_s,IF(t="train",IF(k="","",IFS(AND(k>=1900,k<=2050),1,AND(k>=1850,k<1900),0.7,AND(k>2050,k<=2100),0.7,TRUE,0.2)),IF(k="","",IFS(AND(k>=1700,k<=1850),1,AND(k>=1650,k<1700),0.7,AND(k>1850,k<=1900),0.7,TRUE,0.2))),p_s,IF(t="train",IF(p="","",IFS(AND(p>=125,p<=135),1,AND(p>=115,p<125),0.7,AND(p>135,p<=145),0.7,AND(p>=105,p<115),0.4,AND(p>145,p<=155),0.4,TRUE,0.2)),IF(p="","",IFS(AND(p>=120,p<=130),1,AND(p>=110,p<120),0.7,AND(p>130,p<=140),0.7,AND(p>=100,p<110),0.4,AND(p>140,p<=150),0.4,TRUE,0.2))),f_s,IF(f="","",IFS(AND(f>=55,f<=65),1,AND(f>=50,f<55),0.7,AND(f>65,f<=70),0.7,AND(f>=45,f<50),0.4,AND(f>70,f<=75),0.4,TRUE,0.2)),c_s,IF(t="train",IF(c="","",IFS(AND(c>=180,c<=210),1,AND(c>=160,c<180),0.7,AND(c>210,c<=230),0.7,AND(c>=140,c<160),0.4,AND(c>230,c<=250),0.4,TRUE,0.2)),IF(c="","",IFS(AND(c>=140,c<=170),1,AND(c>=120,c<140),0.7,AND(c>170,c<=190),0.7,AND(c>=100,c<120),0.4,AND(c>190,c<=210),0.4,TRUE,0.2))),AVERAGE(k_s,p_s,f_s,c_s)))),1),"")) | Z92: =IF($A92="","",TEXTJOIN(", ",TRUE,IF($B92="","??????????",""),IF($C92="","??????",""),IF($D92="","????",""),IF($E92="","??????????",""),IF($F92="","???-?????",""),IF($G92="","???-????",""),IF($H92="","??????",""),IF($L92="","???",""),IF($M92="","?????",""),IF($N92="","??????????????",""),IF($O92="","??????????",""),IF($P92="","???????",""),IF($U92="","???","")))
